<?xml version='1.0' encoding='utf8'?>
<mujoco model="base">
    <compiler angle="radian" meshdir="meshes/" />
    <option impratio="20" density="1.2" viscosity="2e-05" cone="elliptic" />
    <size njmax="5000" nconmax="5000" />
    <visual>
        <map znear="0.001" />
    </visual>
    <asset>
        <texture type="skybox" builtin="gradient" rgb1="0.9 0.9 1" rgb2="0.2 0.3 0.4" width="256" height="1536" />
        <texture type="2d" name="texplane" file="/scr/thankyou/autom/robosuite/robosuite/models/assets/arenas/../textures/wood-tiles.png" />
        <texture type="cube" name="tex-ceramic" file="/scr/thankyou/autom/robosuite/robosuite/models/assets/arenas/../textures/ceramic.png" />
        <texture type="cube" name="tex-steel-brushed" file="/scr/thankyou/autom/robosuite/robosuite/models/assets/arenas/../textures/steel-brushed.png" />
        <texture type="2d" name="tex-cream-plaster" file="/scr/thankyou/autom/robosuite/robosuite/models/assets/arenas/../textures/cream-plaster.png" />
        <texture type="cube" name="textable" builtin="flat" rgb1="0.5 0.5 0.5" width="512" height="3072" />
        <texture type="cube" name="cube_redwood" file="/scr/thankyou/autom/robosuite/robosuite/models/assets/textures/red-wood.png" />
        <material name="floorplane" texture="texplane" texuniform="true" texrepeat="2 2" specular="0" shininess="0" reflectance="0.01" />
        <material name="table_ceramic" texture="tex-ceramic" specular="0.2" shininess="0" />
        <material name="table_legs_metal" texture="tex-steel-brushed" shininess="0.8" reflectance="0.8" />
        <material name="walls_mat" texture="tex-cream-plaster" texuniform="true" texrepeat="3 3" specular="0.1" shininess="0.1" />
        <material name="table_mat" texture="textable" />
        <material name="cube_redwood_mat" texture="cube_redwood" specular="0.4" shininess="0.1" />
        <mesh name="robot0_link0" file="/scr/thankyou/autom/robosuite/robosuite/models/assets/robots/panda/meshes/link0.stl" />
        <mesh name="robot0_link1" file="/scr/thankyou/autom/robosuite/robosuite/models/assets/robots/panda/meshes/link1.stl" />
        <mesh name="robot0_link2" file="/scr/thankyou/autom/robosuite/robosuite/models/assets/robots/panda/meshes/link2.stl" />
        <mesh name="robot0_link3" file="/scr/thankyou/autom/robosuite/robosuite/models/assets/robots/panda/meshes/link3.stl" />
        <mesh name="robot0_link4" file="/scr/thankyou/autom/robosuite/robosuite/models/assets/robots/panda/meshes/link4.stl" />
        <mesh name="robot0_link5" file="/scr/thankyou/autom/robosuite/robosuite/models/assets/robots/panda/meshes/link5.stl" />
        <mesh name="robot0_link6" file="/scr/thankyou/autom/robosuite/robosuite/models/assets/robots/panda/meshes/link6.stl" />
        <mesh name="robot0_link7" file="/scr/thankyou/autom/robosuite/robosuite/models/assets/robots/panda/meshes/link7.stl" />
        <mesh name="robot0_link0_vis" file="/scr/thankyou/autom/robosuite/robosuite/models/assets/robots/panda/meshes/link0_vis.stl" />
        <mesh name="robot0_link1_vis" file="/scr/thankyou/autom/robosuite/robosuite/models/assets/robots/panda/meshes/link1_vis.stl" />
        <mesh name="robot0_link2_vis" file="/scr/thankyou/autom/robosuite/robosuite/models/assets/robots/panda/meshes/link2_vis.stl" />
        <mesh name="robot0_link3_vis" file="/scr/thankyou/autom/robosuite/robosuite/models/assets/robots/panda/meshes/link3_vis.stl" />
        <mesh name="robot0_link4_vis" file="/scr/thankyou/autom/robosuite/robosuite/models/assets/robots/panda/meshes/link4_vis.stl" />
        <mesh name="robot0_link5_vis" file="/scr/thankyou/autom/robosuite/robosuite/models/assets/robots/panda/meshes/link5_vis.stl" />
        <mesh name="robot0_link6_vis" file="/scr/thankyou/autom/robosuite/robosuite/models/assets/robots/panda/meshes/link6_vis.stl" />
        <mesh name="robot0_link7_vis" file="/scr/thankyou/autom/robosuite/robosuite/models/assets/robots/panda/meshes/link7_vis.stl" />
        <mesh name="gripper0_robotiq_arg2f_base_link" file="/scr/thankyou/autom/robosuite/robosuite/models/assets/grippers/meshes/robotiq_85_gripper/robotiq_arg2f_base_link.stl" />
        <mesh name="gripper0_robotiq_arg2f_85_outer_knuckle" file="/scr/thankyou/autom/robosuite/robosuite/models/assets/grippers/meshes/robotiq_85_gripper/robotiq_arg2f_85_outer_knuckle.stl" scale="0.001 0.001 0.001" />
        <mesh name="gripper0_robotiq_arg2f_85_outer_finger" file="/scr/thankyou/autom/robosuite/robosuite/models/assets/grippers/meshes/robotiq_85_gripper/robotiq_arg2f_85_outer_finger.stl" scale="0.001 0.001 0.001" />
        <mesh name="gripper0_robotiq_arg2f_85_inner_finger" file="/scr/thankyou/autom/robosuite/robosuite/models/assets/grippers/meshes/robotiq_85_gripper/robotiq_arg2f_85_inner_finger.stl" scale="0.001 0.001 0.001" />
        <mesh name="gripper0_robotiq_arg2f_85_inner_knuckle" file="/scr/thankyou/autom/robosuite/robosuite/models/assets/grippers/meshes/robotiq_85_gripper/robotiq_arg2f_85_inner_knuckle.stl" scale="0.001 0.001 0.001" />
        <mesh name="gripper0_robotiq_arg2f_85_outer_knuckle_vis" file="/scr/thankyou/autom/robosuite/robosuite/models/assets/grippers/meshes/robotiq_85_gripper/robotiq_arg2f_85_outer_knuckle_vis.stl" scale="0.001 0.001 0.001" />
        <mesh name="gripper0_robotiq_arg2f_85_outer_finger_vis" file="/scr/thankyou/autom/robosuite/robosuite/models/assets/grippers/meshes/robotiq_85_gripper/robotiq_arg2f_85_outer_finger_vis.stl" scale="0.001 0.001 0.001" />
        <mesh name="gripper0_robotiq_arg2f_85_inner_finger_vis" file="/scr/thankyou/autom/robosuite/robosuite/models/assets/grippers/meshes/robotiq_85_gripper/robotiq_arg2f_85_inner_finger_vis.stl" scale="0.001 0.001 0.001" />
        <mesh name="gripper0_robotiq_arg2f_85_inner_knuckle_vis" file="/scr/thankyou/autom/robosuite/robosuite/models/assets/grippers/meshes/robotiq_85_gripper/robotiq_arg2f_85_inner_knuckle_vis.stl" scale="0.001 0.001 0.001" />
    </asset>
    <worldbody>
        <geom name="floor" size="3 3 0.125" type="plane" material="floorplane" />
        <geom name="wall_leftcorner_visual" size="1.06 1.5 0.01" pos="-1.25 2.25 1.5" quat="0.653281 0.653281 0.270598 0.270598" type="box" contype="0" conaffinity="0" group="1" material="walls_mat" />
        <geom name="wall_rightcorner_visual" size="1.06 1.5 0.01" pos="-1.25 -2.25 1.5" quat="0.653281 0.653281 -0.270598 -0.270598" type="box" contype="0" conaffinity="0" group="1" material="walls_mat" />
        <geom name="wall_left_visual" size="1.75 1.5 0.01" pos="1.25 3 1.5" quat="0.707107 0.707107 0 0" type="box" contype="0" conaffinity="0" group="1" material="walls_mat" />
        <geom name="wall_right_visual" size="1.75 1.5 0.01" pos="1.25 -3 1.5" quat="0.707107 -0.707107 0 0" type="box" contype="0" conaffinity="0" group="1" material="walls_mat" />
        <geom name="wall_rear_visual" size="1.5 1.5 0.01" pos="-2 0 1.5" quat="0.5 0.5 0.5 0.5" type="box" contype="0" conaffinity="0" group="1" material="walls_mat" />
        <geom name="wall_front_visual" size="3 1.5 0.01" pos="3 0 1.5" quat="0.5 0.5 -0.5 -0.5" type="box" contype="0" conaffinity="0" group="1" material="walls_mat" />
        <camera name="frontview" pos="1.6 0 1.45" quat="0.56 0.43 0.43 0.56" />
        <camera name="birdview" pos="-0.2 0 3" quat="0.7071 0 0 0.7071" />
        <camera name="agentview" pos="0.5 0 1.35" quat="0.653 0.271 0.271 0.653" />
        <camera name="sideview" pos="-0.0565177 1.27612 1.48796" quat="0.00990507 0.00687796 0.591223 0.806418" />
        <light name="light1" pos="1 1 4" dir="0 -0.14834 -0.988936" castshadow="false" diffuse="0.8 0.8 0.8" />
        <light name="light2" pos="-3 -3 4" dir="0 -0.14834 -0.988936" castshadow="false" diffuse="0.8 0.8 0.8" />
        <camera mode="fixed" name="27432424_left" pos="0.1946723527791488 -0.42610897205557197 0.4304268265555512" quat="0.7826180975611038 0.5625120734850436 -0.1441474008438781 -0.22430026166580733" fovy="68.94"/>
        <body name="robot0_base" pos="0 0 0">
            <inertial pos="0 0 0" mass="0" diaginertia="0 0 0" />
            <camera name="robot0_robotview" pos="1 0 0.4" quat="0.653 0.271 0.271 0.653" />
            <body name="robot0_link0" pos="0 0 0">
                <inertial pos="0 0 0.05" mass="4" diaginertia="0.4 0.4 0.4" />
                <geom name="robot0_link0_visual" type="mesh" contype="0" conaffinity="0" group="1" rgba="1 1 1 1" mesh="robot0_link0_vis" />
                <geom name="robot0_link0_collision" type="mesh" rgba="0 0.5 0 1" mesh="robot0_link0" />
                <body name="robot0_link1" pos="0 0 0.333">
                    <inertial pos="0 0 -0.07" mass="3" diaginertia="0.3 0.3 0.3" />
                    <joint name="robot0_joint1" pos="0 0 0" axis="0 0 1" limited="true" range="-2.8973 2.8973" armature="5" damping="0.1" frictionloss="0.1" />
                    <geom name="robot0_link1_visual" type="mesh" contype="0" conaffinity="0" group="1" rgba="1 1 1 1" mesh="robot0_link1_vis" />
                    <geom name="robot0_link1_collision" type="mesh" rgba="0 0.5 0 1" mesh="robot0_link1" />
                    <body name="robot0_link2" pos="0 0 0" quat="0.707107 -0.707107 0 0">
                        <inertial pos="0 -0.1 0" mass="3" diaginertia="0.3 0.3 0.3" />
                        <joint name="robot0_joint2" pos="0 0 0" axis="0 0 1" limited="true" range="-1.7628 1.7628" armature="2.5" damping="0.1" frictionloss="0.1" />
                        <geom name="robot0_link2_visual" type="mesh" contype="0" conaffinity="0" group="1" rgba="1 1 1 1" mesh="robot0_link2_vis" />
                        <geom name="robot0_link2_collision" type="mesh" rgba="0 0.5 0 1" mesh="robot0_link2" />
                        <body name="robot0_link3" pos="0 -0.316 0" quat="0.707107 0.707107 0 0">
                            <inertial pos="0.04 0 -0.05" mass="2" diaginertia="0.2 0.2 0.2" />
                            <joint name="robot0_joint3" pos="0 0 0" axis="0 0 1" limited="true" range="-2.8973 2.8973" armature="1.66667" damping="0.1" frictionloss="0.1" />
                            <geom name="robot0_link3_visual" type="mesh" contype="0" conaffinity="0" group="1" rgba="1 1 1 1" mesh="robot0_link3_vis" />
                            <geom name="robot0_link3_collision" type="mesh" rgba="0 0.5 0 1" mesh="robot0_link3" />
                            <body name="robot0_link4" pos="0.0825 0 0" quat="0.707107 0.707107 0 0">
                                <inertial pos="-0.04 0.05 0" mass="2" diaginertia="0.2 0.2 0.2" />
                                <joint name="robot0_joint4" pos="0 0 0" axis="0 0 1" limited="true" range="-3.0718 -0.0698" armature="1.25" damping="0.1" frictionloss="0.1" />
                                <geom name="robot0_link4_visual" type="mesh" contype="0" conaffinity="0" group="1" rgba="1 1 1 1" mesh="robot0_link4_vis" />
                                <geom name="robot0_link4_collision" type="mesh" rgba="0 0.5 0 1" mesh="robot0_link4" />
                                <body name="robot0_link5" pos="-0.0825 0.384 0" quat="0.707107 -0.707107 0 0">
                                    <inertial pos="0 0 -0.15" mass="2" diaginertia="0.2 0.2 0.2" />
                                    <joint name="robot0_joint5" pos="0 0 0" axis="0 0 1" limited="true" range="-2.8973 2.8973" armature="1" damping="0.1" frictionloss="0.1" />
                                    <geom name="robot0_link5_visual" type="mesh" contype="0" conaffinity="0" group="1" rgba="1 1 1 1" mesh="robot0_link5_vis" />
                                    <geom name="robot0_link5_collision" type="mesh" rgba="0 0.5 0 1" mesh="robot0_link5" />
                                    <body name="robot0_link6" pos="0 0 0" quat="0.707107 0.707107 0 0">
                                        <inertial pos="0.06 0 0" mass="1.5" diaginertia="0.1 0.1 0.1" />
                                        <joint name="robot0_joint6" pos="0 0 0" axis="0 0 1" limited="true" range="-0.0175 3.7525" armature="0.833333" damping="0.01" frictionloss="0.1" />
                                        <geom name="robot0_link6_visual" type="mesh" contype="0" conaffinity="0" group="1" rgba="1 1 1 1" mesh="robot0_link6_vis" />
                                        <geom name="robot0_link6_collision" type="mesh" rgba="0 0.5 0 1" mesh="robot0_link6" />
                                        <body name="robot0_link7" pos="0.088 0 0" quat="0.707107 0.707107 0 0">
                                            <inertial pos="0 0 0.08" mass="0.5" diaginertia="0.05 0.05 0.05" />
                                            <joint name="robot0_joint7" pos="0 0 0" axis="0 0 1" limited="true" range="-2.8973 2.8973" armature="0.714286" damping="0.01" frictionloss="0.1" />
                                            <geom name="robot0_link7_visual" type="mesh" contype="0" conaffinity="0" group="1" rgba="1 1 1 1" mesh="robot0_link7_vis" />
                                            <geom name="robot0_link7_collision" type="mesh" rgba="0 0.5 0 1" mesh="robot0_link7" />
                                            <body name="robot0_right_hand" pos="0 0 0.107" quat="1 0 0 0">
                                                <inertial pos="0 0 0" mass="0.5" diaginertia="0.05 0.05 0.05" />
                                                <site name="robot0_ee" pos="0 0 0" size="0.01" group="1" rgba="0 0 1 1" />
                                                <site name="robot0_ee_x" pos="0 0 0" quat="0.707105 0.707108 0 0" size="0.005 0.1" group="1" type="cylinder" rgba="1 0 0 0" />
                                                <site name="robot0_ee_z" pos="0 0 0" quat="0.707105 0 0 0.707108" size="0.005 0.1" group="1" type="cylinder" rgba="0 0 1 0" />
                                                <site name="robot0_ee_y" pos="0 0 0" quat="0.707105 0 0.707108 0" size="0.005 0.1" group="1" type="cylinder" rgba="0 1 0 0" />
                                                <camera name="robot0_eye_in_hand" pos="0.05 0 0" quat="0 0.707108 0.707108 0" fovy="75" />
                                                <body name="gripper0_robotiq_85_adapter_link" pos="0 0 0">
                                                    <inertial pos="0 0 0" mass="0.01" diaginertia="0.001 0.001 0.001" />
                                                    <geom name="gripper0_hand_visual" type="mesh" contype="0" conaffinity="0" group="1" rgba="0.1 0.1 0.1 1" mesh="gripper0_robotiq_arg2f_base_link" />
                                                    <geom name="gripper0_hand_collision" type="mesh" rgba="0 0 0.5 1" mesh="gripper0_robotiq_arg2f_base_link" />
                                                    <site name="gripper0_ft_frame" pos="0 0 0" size="0.01" group="1" rgba="1 0 0 1" />
                                                    <site name="gripper0_grip_site" pos="0 0 0.145" size="0.01" group="1" rgba="1 0 0 0.5" />
                                                    <site name="gripper0_grip_site_cylinder" pos="0 0 0.145" size="0.005 10" group="1" type="cylinder" rgba="0 1 0 0.3" />
                                                    <body name="gripper0_left_outer_knuckle" pos="0 -0.0306011 0.054904" quat="0 0 0 1">
                                                        <inertial pos="0.000163875 0.0554825 -0.0100755" quat="0.920541 0.390623 -0.00362953 0.00231744" mass="0.0311462" diaginertia="5.11372e-05 4.89464e-05 4.95906e-06" />
                                                        <joint name="gripper0_finger_joint" pos="0 0 0" axis="1 0 0" limited="true" range="0 0.8" />
                                                        <geom name="gripper0_left_outer_knuckle_visual" type="mesh" contype="0" conaffinity="0" group="1" rgba="0.792157 0.819608 0.933333 1" mesh="gripper0_robotiq_arg2f_85_outer_knuckle_vis" />
                                                        <geom name="gripper0_left_outer_knuckle_collision" type="mesh" solref="0.01 0.25" rgba="0 0 0.5 1" mesh="gripper0_robotiq_arg2f_85_outer_knuckle" />
                                                        <geom name="gripper0_left_outer_finger_visual" pos="0 0.0315 -0.0041" type="mesh" contype="0" conaffinity="0" group="1" rgba="0.1 0.1 0.1 1" mesh="gripper0_robotiq_arg2f_85_outer_finger_vis" />
                                                        <geom name="gripper0_left_outer_finger_collision" pos="0 0.0315 -0.0041" type="mesh" solref="0.01 0.25" rgba="0 0 0.5 1" mesh="gripper0_robotiq_arg2f_85_outer_finger" />
                                                        <body name="gripper0_left_inner_finger" pos="0 0.0376 0.043">
                                                            <inertial pos="0.000199506 0.0032692 0.00175282" quat="0.933621 0.35825 -0.00273441 0.00104851" mass="0.0156391" diaginertia="1.57977e-05 1.51089e-05 1.4647e-06" />
                                                            <joint name="gripper0_left_inner_finger_joint" pos="0 0 0" axis="1 0 0" limited="true" range="-0.8757 0.8757" />
                                                            <geom name="gripper0_left_inner_finger_visual" type="mesh" contype="0" conaffinity="0" group="1" rgba="0.1 0.1 0.1 1" mesh="gripper0_robotiq_arg2f_85_inner_finger_vis" />
                                                            <geom name="gripper0_left_inner_finger_collision" type="mesh" solref="0.01 0.25" rgba="0 0 0.5 1" mesh="gripper0_robotiq_arg2f_85_inner_finger" />
                                                            <geom name="gripper0_left_fingertip_visual" size="0.011 0.003175 0.01875" pos="0 -0.0220203 0.03242" type="box" contype="0" conaffinity="0" group="1" rgba="0.9 0.9 0.9 1" />
                                                            <geom name="gripper0_left_fingertip_collision" size="0.011 0.003175 0.01875" pos="0 -0.0220203 0.03242" type="box" solref="0.01 0.25" rgba="0 0 0.5 1" />
                                                            <geom name="gripper0_left_fingerpad_collision" size="0.01 0.001 0.01675" pos="0 -0.0245203 0.03242" type="box" rgba="0 0 0.5 1" />
                                                        </body>
                                                    </body>
                                                    <body name="gripper0_left_inner_knuckle" pos="0 -0.0127 0.06142" quat="0 0 0 1">
                                                        <inertial pos="0.000123012 0.0507851 0.00103969" quat="0.497203 0.502496 -0.507943 0.492221" mass="0.0271177" diaginertia="2.83809e-05 2.61936e-05 2.81319e-06" />
                                                        <joint name="gripper0_left_inner_knuckle_joint" pos="0 0 0" axis="1 0 0" limited="true" range="0 0.8757" />
                                                        <geom name="gripper0_left_inner_knuckle_visual" type="mesh" contype="0" conaffinity="0" group="1" rgba="0.1 0.1 0.1 1" mesh="gripper0_robotiq_arg2f_85_inner_knuckle_vis" />
                                                        <geom name="gripper0_left_inner_knuckle_collision" type="mesh" rgba="0 0 0.5 1" mesh="gripper0_robotiq_arg2f_85_inner_knuckle" />
                                                    </body>
                                                    <body name="gripper0_right_outer_knuckle" pos="0 0.0306011 0.054904">
                                                        <inertial pos="0.000163875 0.0554825 -0.0100755" quat="0.920541 0.390623 -0.00362953 0.00231744" mass="0.0311462" diaginertia="5.11372e-05 4.89464e-05 4.95906e-06" />
                                                        <joint name="gripper0_right_outer_knuckle_joint" pos="0 0 0" axis="1 0 0" limited="true" range="0 0.8" />
                                                        <geom name="gripper0_right_outer_knuckle_visual" type="mesh" contype="0" conaffinity="0" group="1" rgba="0.792157 0.819608 0.933333 1" mesh="gripper0_robotiq_arg2f_85_outer_knuckle_vis" />
                                                        <geom name="gripper0_right_outer_knuckle_collision" type="mesh" solref="0.01 0.25" rgba="0 0 0.5 1" mesh="gripper0_robotiq_arg2f_85_outer_knuckle" />
                                                        <geom name="gripper0_right_outer_finger_visual" pos="0 0.0315 -0.0041" type="mesh" contype="0" conaffinity="0" group="1" rgba="0.1 0.1 0.1 1" mesh="gripper0_robotiq_arg2f_85_outer_finger_vis" />
                                                        <geom name="gripper0_right_outer_finger_collision" pos="0 0.0315 -0.0041" type="mesh" solref="0.01 0.25" rgba="0 0 0.5 1" mesh="gripper0_robotiq_arg2f_85_outer_finger" />
                                                        <body name="gripper0_right_inner_finger" pos="0 0.0376 0.043">
                                                            <inertial pos="0.000199506 0.0032692 0.00175282" quat="0.933621 0.35825 -0.00273441 0.00104851" mass="0.0156391" diaginertia="1.57977e-05 1.51089e-05 1.4647e-06" />
                                                            <joint name="gripper0_right_inner_finger_joint" pos="0 0 0" axis="1 0 0" limited="true" range="-0.8757 0.8757" />
                                                            <geom name="gripper0_right_inner_finger_visual" type="mesh" contype="0" conaffinity="0" group="1" rgba="0.1 0.1 0.1 1" mesh="gripper0_robotiq_arg2f_85_inner_finger_vis" />
                                                            <geom name="gripper0_right_inner_finger_collision" type="mesh" solref="0.01 0.25" rgba="0 0 0.5 1" mesh="gripper0_robotiq_arg2f_85_inner_finger" />
                                                            <geom name="gripper0_right_fingertip_visual" size="0.011 0.003175 0.01875" pos="0 -0.0220203 0.03242" type="box" contype="0" conaffinity="0" group="1" rgba="0.9 0.9 0.9 1" />
                                                            <geom name="gripper0_right_fingertip_collision" size="0.011 0.003175 0.01875" pos="0 -0.0220203 0.03242" type="box" solref="0.01 0.25" rgba="0 0 0.5 1" />
                                                            <geom name="gripper0_right_fingerpad_collision" size="0.01 0.001 0.01675" pos="0 -0.0245203 0.03242" type="box" rgba="0 0 0.5 1" />
                                                        </body>
                                                    </body>
                                                    <body name="gripper0_right_inner_knuckle" pos="0 0.0127 0.06142">
                                                        <inertial pos="0.000123012 0.0507851 0.00103969" quat="0.497203 0.502496 -0.507943 0.492221" mass="0.0271177" diaginertia="2.83809e-05 2.61936e-05 2.81319e-06" />
                                                        <joint name="gripper0_right_inner_knuckle_joint" pos="0 0 0" axis="1 0 0" limited="true" range="0 0.8757" />
                                                        <geom name="gripper0_right_inner_knuckle_visual" type="mesh" contype="0" conaffinity="0" group="1" rgba="0.1 0.1 0.1 1" mesh="gripper0_robotiq_arg2f_85_inner_knuckle_vis" />
                                                        <geom name="gripper0_right_inner_knuckle_collision" type="mesh" rgba="0 0 0.5 1" mesh="gripper0_robotiq_arg2f_85_inner_knuckle" />
                                                    </body>
                                                </body>
                                                <camera mode="fixed" name="12391924_left" pos="-0.07644216443928634, -0.02730158707694055, 0.012627235466440005" quat="-0.11325485778077442 -0.6906656258244279 0.7026997954670453 0.12793485820596612" fovy="52.409042906351495" />
                                            </body>
                                        </body>
                                    </body>
                                </body>
                            </body>
                        </body>
                    </body>
                </body>
            </body>
            <body name="mount0_base" pos="0 0 0">
                <inertial pos="0 0 0" mass="0" diaginertia="0 0 0" />
            </body>
        </body>
        <body name="cube_main" pos="0 0 0">
            <inertial pos="0 0 0" mass="0.0743781" diaginertia="2.16306e-05 2.16224e-05 2.25755e-05" />
            <joint name="cube_joint0" type="free" />
            <geom name="cube_g0" size="0.0213335 0.0213413 0.0204208" type="box" rgba="0.5 0 0 1" />
            <geom name="cube_g0_vis" size="0.0213335 0.0213413 0.0204208" type="box" contype="0" conaffinity="0" group="1" material="cube_redwood_mat" />
            <site name="cube_default_site" pos="0 0 0" size="0.002" rgba="1 0 0 1" />
        </body>
    </worldbody>
    <tendon>
        <fixed name="gripper0_finger2_12_cpl" range="-1 1" stiffness="0.4" springlength="0.001">
            <joint joint="gripper0_finger_joint" coef="1" />
            <joint joint="gripper0_left_inner_finger_joint" coef="-3" />
            <joint joint="gripper0_left_inner_knuckle_joint" coef="1" />
        </fixed>
        <fixed name="gripper0_finger1_12_cpl" range="-1 1" stiffness="0.4" springlength="0.001">
            <joint joint="gripper0_right_outer_knuckle_joint" coef="1" />
            <joint joint="gripper0_right_inner_finger_joint" coef="-3" />
            <joint joint="gripper0_right_inner_knuckle_joint" coef="1" />
        </fixed>
    </tendon>
    <actuator>
        <general name="robot0_torq_j1" joint="robot0_joint1" ctrllimited="true" ctrlrange="-80 80" />
        <general name="robot0_torq_j2" joint="robot0_joint2" ctrllimited="true" ctrlrange="-80 80" />
        <general name="robot0_torq_j3" joint="robot0_joint3" ctrllimited="true" ctrlrange="-80 80" />
        <general name="robot0_torq_j4" joint="robot0_joint4" ctrllimited="true" ctrlrange="-80 80" />
        <general name="robot0_torq_j5" joint="robot0_joint5" ctrllimited="true" ctrlrange="-80 80" />
        <general name="robot0_torq_j6" joint="robot0_joint6" ctrllimited="true" ctrlrange="-12 12" />
        <general name="robot0_torq_j7" joint="robot0_joint7" ctrllimited="true" ctrlrange="-12 12" />
        <general name="gripper0_finger_1" joint="gripper0_finger_joint" ctrllimited="true" ctrlrange="0 0.8" biastype="affine" gainprm="20 0 0 0 0 0 0 0 0 0" biasprm="0 -20 0 0 0 0 0 0 0 0" />
        <general name="gripper0_finger_2" joint="gripper0_right_outer_knuckle_joint" ctrllimited="true" ctrlrange="0 0.8" biastype="affine" gainprm="20 0 0 0 0 0 0 0 0 0" biasprm="0 -20 0 0 0 0 0 0 0 0" />
    </actuator>
    <sensor>
        <force site="gripper0_ft_frame" name="gripper0_force_ee" />
        <torque site="gripper0_ft_frame" name="gripper0_torque_ee" />
    </sensor>
</mujoco>